[2024-11-10T11:36:46.292+0000] {local_task_job_runner.py:123} INFO - ::group::Pre task execution logs
[2024-11-10T11:36:46.423+0000] {taskinstance.py:2613} INFO - Dependencies all met for dep_context=non-requeueable deps ti=<TaskInstance: fetch_and_store_amazon_books.insert_book_data scheduled__2024-06-28T00:00:00+00:00 [queued]>
[2024-11-10T11:36:46.500+0000] {taskinstance.py:2613} INFO - Dependencies all met for dep_context=requeueable deps ti=<TaskInstance: fetch_and_store_amazon_books.insert_book_data scheduled__2024-06-28T00:00:00+00:00 [queued]>
[2024-11-10T11:36:46.501+0000] {taskinstance.py:2866} INFO - Starting attempt 2 of 2
[2024-11-10T11:36:46.549+0000] {taskinstance.py:2889} INFO - Executing <Task(PythonOperator): insert_book_data> on 2024-06-28 00:00:00+00:00
[2024-11-10T11:36:46.648+0000] {warnings.py:112} WARNING - /home/***/.local/lib/python3.12/site-packages/***/task/task_runner/standard_task_runner.py:70: DeprecationWarning: This process (pid=1327) is multi-threaded, use of fork() may lead to deadlocks in the child.
  pid = os.fork()

[2024-11-10T11:36:46.657+0000] {standard_task_runner.py:72} INFO - Started process 1333 to run task
[2024-11-10T11:36:46.693+0000] {standard_task_runner.py:104} INFO - Running: ['***', 'tasks', 'run', 'fetch_and_store_amazon_books', 'insert_book_data', 'scheduled__2024-06-28T00:00:00+00:00', '--job-id', '63', '--raw', '--subdir', 'DAGS_FOLDER/app.py', '--cfg-path', '/tmp/tmp0nzto3k4']
[2024-11-10T11:36:46.730+0000] {standard_task_runner.py:105} INFO - Job 63: Subtask insert_book_data
[2024-11-10T11:36:47.010+0000] {task_command.py:467} INFO - Running <TaskInstance: fetch_and_store_amazon_books.insert_book_data scheduled__2024-06-28T00:00:00+00:00 [running]> on host 0afc8c4a15bb
[2024-11-10T11:36:47.628+0000] {taskinstance.py:3132} INFO - Exporting env vars: AIRFLOW_CTX_DAG_OWNER='***' AIRFLOW_CTX_DAG_ID='fetch_and_store_amazon_books' AIRFLOW_CTX_TASK_ID='insert_book_data' AIRFLOW_CTX_EXECUTION_DATE='2024-06-28T00:00:00+00:00' AIRFLOW_CTX_TRY_NUMBER='2' AIRFLOW_CTX_DAG_RUN_ID='scheduled__2024-06-28T00:00:00+00:00'
[2024-11-10T11:36:47.632+0000] {logging_mixin.py:190} INFO - Task instance is in running state
[2024-11-10T11:36:47.633+0000] {logging_mixin.py:190} INFO -  Previous state of the Task instance: queued
[2024-11-10T11:36:47.634+0000] {logging_mixin.py:190} INFO - Current task name:insert_book_data state:running start_date:2024-11-10 11:36:46.424588+00:00
[2024-11-10T11:36:47.634+0000] {logging_mixin.py:190} INFO - Dag name:fetch_and_store_amazon_books and current dag run status:running
[2024-11-10T11:36:47.635+0000] {taskinstance.py:731} INFO - ::endgroup::
[2024-11-10T11:36:47.704+0000] {taskinstance.py:3311} ERROR - Task failed with exception
Traceback (most recent call last):
  File "/home/airflow/.local/lib/python3.12/site-packages/airflow/models/taskinstance.py", line 767, in _execute_task
    result = _execute_callable(context=context, **execute_callable_kwargs)
             ^^^^^^^^^^^^^^^^^^^^^^^^^^^^^^^^^^^^^^^^^^^^^^^^^^^^^^^^^^^^^
  File "/home/airflow/.local/lib/python3.12/site-packages/airflow/models/taskinstance.py", line 733, in _execute_callable
    return ExecutionCallableRunner(
           ^^^^^^^^^^^^^^^^^^^^^^^^
  File "/home/airflow/.local/lib/python3.12/site-packages/airflow/utils/operator_helpers.py", line 252, in run
    return self.func(*args, **kwargs)
           ^^^^^^^^^^^^^^^^^^^^^^^^^^
  File "/home/airflow/.local/lib/python3.12/site-packages/airflow/models/baseoperator.py", line 417, in wrapper
    return func(self, *args, **kwargs)
           ^^^^^^^^^^^^^^^^^^^^^^^^^^^
  File "/home/airflow/.local/lib/python3.12/site-packages/airflow/operators/python.py", line 238, in execute
    return_value = self.execute_callable()
                   ^^^^^^^^^^^^^^^^^^^^^^^
  File "/home/airflow/.local/lib/python3.12/site-packages/airflow/operators/python.py", line 256, in execute_callable
    return runner.run(*self.op_args, **self.op_kwargs)
           ^^^^^^^^^^^^^^^^^^^^^^^^^^^^^^^^^^^^^^^^^^^
  File "/home/airflow/.local/lib/python3.12/site-packages/airflow/utils/operator_helpers.py", line 252, in run
    return self.func(*args, **kwargs)
           ^^^^^^^^^^^^^^^^^^^^^^^^^^
  File "/opt/airflow/dags/app.py", line 95, in insert_book_data_into_postgres
    raise ValueError("No book data found")
ValueError: No book data found
[2024-11-10T11:36:47.735+0000] {logging_mixin.py:190} INFO - Task instance in failure state
[2024-11-10T11:36:47.736+0000] {logging_mixin.py:190} INFO - Task start:2024-11-10 11:36:46.424588+00:00 end:2024-11-10 11:36:47.734260+00:00 duration:1.309672
[2024-11-10T11:36:47.737+0000] {logging_mixin.py:190} INFO - Task:<Task(PythonOperator): insert_book_data> dag:<DAG: fetch_and_store_amazon_books> dagrun:<DagRun fetch_and_store_amazon_books @ 2024-06-28 00:00:00+00:00: scheduled__2024-06-28T00:00:00+00:00, state:running, queued_at: 2024-11-10 11:30:17.872652+00:00. externally triggered: False>
[2024-11-10T11:36:47.738+0000] {logging_mixin.py:190} INFO - Failure caused by No book data found
[2024-11-10T11:36:47.738+0000] {taskinstance.py:1225} INFO - Marking task as FAILED. dag_id=fetch_and_store_amazon_books, task_id=insert_book_data, run_id=scheduled__2024-06-28T00:00:00+00:00, execution_date=20240628T000000, start_date=20241110T113646, end_date=20241110T113647
[2024-11-10T11:36:47.770+0000] {taskinstance.py:340} INFO - ::group::Post task execution logs
[2024-11-10T11:36:47.771+0000] {standard_task_runner.py:124} ERROR - Failed to execute job 63 for task insert_book_data (No book data found; 1333)
Traceback (most recent call last):
  File "/home/airflow/.local/lib/python3.12/site-packages/airflow/task/task_runner/standard_task_runner.py", line 117, in _start_by_fork
    ret = args.func(args, dag=self.dag)
          ^^^^^^^^^^^^^^^^^^^^^^^^^^^^^
  File "/home/airflow/.local/lib/python3.12/site-packages/airflow/cli/cli_config.py", line 49, in command
    return func(*args, **kwargs)
           ^^^^^^^^^^^^^^^^^^^^^
  File "/home/airflow/.local/lib/python3.12/site-packages/airflow/utils/cli.py", line 116, in wrapper
    return f(*args, **kwargs)
           ^^^^^^^^^^^^^^^^^^
  File "/home/airflow/.local/lib/python3.12/site-packages/airflow/cli/commands/task_command.py", line 483, in task_run
    task_return_code = _run_task_by_selected_method(args, _dag, ti)
                       ^^^^^^^^^^^^^^^^^^^^^^^^^^^^^^^^^^^^^^^^^^^^
  File "/home/airflow/.local/lib/python3.12/site-packages/airflow/cli/commands/task_command.py", line 256, in _run_task_by_selected_method
    return _run_raw_task(args, ti)
           ^^^^^^^^^^^^^^^^^^^^^^^
  File "/home/airflow/.local/lib/python3.12/site-packages/airflow/cli/commands/task_command.py", line 341, in _run_raw_task
    return ti._run_raw_task(
           ^^^^^^^^^^^^^^^^^
  File "/home/airflow/.local/lib/python3.12/site-packages/airflow/utils/session.py", line 97, in wrapper
    return func(*args, session=session, **kwargs)
           ^^^^^^^^^^^^^^^^^^^^^^^^^^^^^^^^^^^^^^
  File "/home/airflow/.local/lib/python3.12/site-packages/airflow/models/taskinstance.py", line 3005, in _run_raw_task
    return _run_raw_task(
           ^^^^^^^^^^^^^^
  File "/home/airflow/.local/lib/python3.12/site-packages/airflow/models/taskinstance.py", line 273, in _run_raw_task
    TaskInstance._execute_task_with_callbacks(
  File "/home/airflow/.local/lib/python3.12/site-packages/airflow/models/taskinstance.py", line 3159, in _execute_task_with_callbacks
    result = self._execute_task(context, task_orig)
             ^^^^^^^^^^^^^^^^^^^^^^^^^^^^^^^^^^^^^^
  File "/home/airflow/.local/lib/python3.12/site-packages/airflow/models/taskinstance.py", line 3183, in _execute_task
    return _execute_task(self, context, task_orig)
           ^^^^^^^^^^^^^^^^^^^^^^^^^^^^^^^^^^^^^^^
  File "/home/airflow/.local/lib/python3.12/site-packages/airflow/models/taskinstance.py", line 767, in _execute_task
    result = _execute_callable(context=context, **execute_callable_kwargs)
             ^^^^^^^^^^^^^^^^^^^^^^^^^^^^^^^^^^^^^^^^^^^^^^^^^^^^^^^^^^^^^
  File "/home/airflow/.local/lib/python3.12/site-packages/airflow/models/taskinstance.py", line 733, in _execute_callable
    return ExecutionCallableRunner(
           ^^^^^^^^^^^^^^^^^^^^^^^^
  File "/home/airflow/.local/lib/python3.12/site-packages/airflow/utils/operator_helpers.py", line 252, in run
    return self.func(*args, **kwargs)
           ^^^^^^^^^^^^^^^^^^^^^^^^^^
  File "/home/airflow/.local/lib/python3.12/site-packages/airflow/models/baseoperator.py", line 417, in wrapper
    return func(self, *args, **kwargs)
           ^^^^^^^^^^^^^^^^^^^^^^^^^^^
  File "/home/airflow/.local/lib/python3.12/site-packages/airflow/operators/python.py", line 238, in execute
    return_value = self.execute_callable()
                   ^^^^^^^^^^^^^^^^^^^^^^^
  File "/home/airflow/.local/lib/python3.12/site-packages/airflow/operators/python.py", line 256, in execute_callable
    return runner.run(*self.op_args, **self.op_kwargs)
           ^^^^^^^^^^^^^^^^^^^^^^^^^^^^^^^^^^^^^^^^^^^
  File "/home/airflow/.local/lib/python3.12/site-packages/airflow/utils/operator_helpers.py", line 252, in run
    return self.func(*args, **kwargs)
           ^^^^^^^^^^^^^^^^^^^^^^^^^^
  File "/opt/airflow/dags/app.py", line 95, in insert_book_data_into_postgres
    raise ValueError("No book data found")
ValueError: No book data found
[2024-11-10T11:36:47.860+0000] {local_task_job_runner.py:266} INFO - Task exited with return code 1
[2024-11-10T11:36:47.979+0000] {taskinstance.py:3895} INFO - 0 downstream tasks scheduled from follow-on schedule check
[2024-11-10T11:36:47.983+0000] {local_task_job_runner.py:245} INFO - ::endgroup::
